<robot
  name="tom_3d">
  <link
    name="base_link">
    <inertial>
      <origin
        xyz="-0.14913 0.12396 0.20022"
        rpy="0 0 0" />
      <mass
        value="30.638" />
      <inertia
        ixx="0.87599"
        ixy="0.0041843"
        ixz="0.0027897"
        iyy="0.39695"
        iyz="-0.32976"
        izz="0.62325" />
    </inertial>
    <visual>
      <origin
        xyz="0 0 0"
        rpy="0 0 0" />
      <geometry>
        <mesh
          filename="package://tom3d_simulation/meshes/base_link.STL" scale="0.001 0.001 0.001" />
      </geometry>
      <material
        name="">
        <color
          rgba="0.29804 0.29804 0.29804 1" />
      </material>
    </visual>
    <collision>
      <origin
        xyz="0 0 0"
        rpy="0 0 0" />
      <geometry>
        <mesh
          filename="package://tom3d_simulation/meshes/base_link.STL" scale="0.001 0.001 0.001"/>
      </geometry>
    </collision>
  </link>
  <link
    name="left_wheel_Link">
    <inertial>
      <origin
        xyz="-5.1086E-07 7.6201E-09 7.8965E-07"
        rpy="0 0 0" />
      <mass
        value="0.47973" />
      <inertia
        ixx="0.00083852"
        ixy="-6.1273E-10"
        ixz="-2.7632E-08"
        iyy="0.0015699"
        iyz="1.1061E-09"
        izz="0.00083854" />
    </inertial>
    <visual>
      <origin
        xyz="0 0 0"
        rpy="0 0 0" />
      <geometry>
        <mesh
          filename="package://tom3d_simulation/meshes/left_wheel_Link.STL" />
      </geometry>
      <material
        name="">
        <color
          rgba="0.29804 0.29804 0.29804 1" />
      </material>
    </visual>
    <collision>
      <origin
        xyz="0 0 0"
        rpy="0 0 0" />
      <geometry>
        <mesh
          filename="package://tom3d_simulation/meshes/left_wheel_Link.STL" />
      </geometry>
    </collision>
  </link>
  <joint
    name="left_wheel_joint"
    type="continuous">
    <origin
      xyz="0.0073335 -0.20028 -0.19107"
      rpy="0 -6.123E-17 -1.5708" />
    <parent
      link="base_link" />
    <child
      link="left_wheel_Link" />
    <axis
      xyz="0 1 0" />
  </joint>
  <link
    name="right_wheel_Link">
    <inertial>
      <origin
        xyz="9.0179E-07 -7.6201E-09 2.67E-07"
        rpy="0 0 0" />
      <mass
        value="0.47973" />
      <inertia
        ixx="0.00083856"
        ixy="-1.1851E-09"
        ixz="1.2773E-08"
        iyy="0.0015699"
        iyz="-4.4092E-10"
        izz="0.00083851" />
    </inertial>
    <visual>
      <origin
        xyz="0 0 0"
        rpy="0 0 0" />
      <geometry>
        <mesh
          filename="package://tom3d_simulation/meshes/right_wheel_Link.STL" />
      </geometry>
      <material
        name="">
        <color
          rgba="0.29804 0.29804 0.29804 1" />
      </material>
    </visual>
    <collision>
      <origin
        xyz="0 0 0"
        rpy="0 0 0" />
      <geometry>
        <mesh
          filename="package://tom3d_simulation/meshes/right_wheel_Link.STL" />
      </geometry>
    </collision>
  </link>
  <joint
    name="right_wheel_joint"
    type="continuous">
    <origin
      xyz="-0.29946 -0.20028 -0.19107"
      rpy="0 -6.123E-17 -1.5708" />
    <parent
      link="base_link" />
    <child
      link="right_wheel_Link" />
    <axis
      xyz="0 1 0" />
  </joint>
  <link
    name="caster_wheel_Link">
    <inertial>
      <origin
        xyz="-0.38482 -8.5026E-05 -0.00017371"
        rpy="0 0 0" />
      <mass
        value="2.7081" />
      <inertia
        ixx="0.0030526"
        ixy="-1.4924E-06"
        ixz="-0.00090739"
        iyy="0.0040132"
        iyz="-3.3493E-06"
        izz="0.0017751" />
    </inertial>
    <visual>
      <origin
        xyz="0 0 0"
        rpy="0 0 0" />
      <geometry>
        <mesh
          filename="package://tom3d_simulation/meshes/caster_wheel_Link.STL" />
      </geometry>
      <material
        name="">
        <color
          rgba="0.2 0.2 0.2 1" />
      </material>
    </visual>
    <collision>
      <origin
        xyz="0 0 0"
        rpy="0 0 0" />
      <geometry>
        <mesh
          filename="package://tom3d_simulation/meshes/caster_wheel_Link.STL" />
      </geometry>
    </collision>
  </link>
  <joint
    name="caster_wheel_joint"
    type="fixed">
    <origin
      xyz="-0.14606 -0.28069 -0.21807"
      rpy="0 -6.123E-17 -1.5708" />
    <parent
      link="base_link" />
    <child
      link="caster_wheel_Link" />
    <axis
      xyz="0 0 0" />
  </joint>
  <link
    name="sick_pls_Link">
    <inertial>
      <origin
        xyz="3.2181E-09 0.0005964 0.07464"
        rpy="0 0 0" />
      <mass
        value="26.971" />
      <inertia
        ixx="0.12444"
        ixy="1.4883E-08"
        ixz="-3.6234E-08"
        iyy="0.094836"
        iyz="-0.009259"
        izz="0.12755" />
    </inertial>
    <visual>
      <origin
        xyz="0 0 0"
        rpy="0 0 0" />
      <geometry>
        <mesh
          filename="package://tom3d_simulation/meshes/sick_pls_Link.STL" />
      </geometry>
      <material
        name="">
        <color
          rgba="0.2 0.2 0.2 1" />
      </material>
    </visual>
    <collision>
      <origin
        xyz="0 0 0"
        rpy="0 0 0" />
      <geometry>
        <mesh
          filename="package://tom3d_simulation/meshes/sick_pls_Link.STL" />
      </geometry>
    </collision>
  </link>
  <joint
    name="sick_pls_joint"
    type="fixed">
    <origin
      xyz="-0.14954 -0.15614 0.16893"
      rpy="1.5708 0 0" />
    <parent
      link="base_link" />
    <child
      link="sick_pls_Link" />
    <axis
      xyz="0 0 0" />
  </joint>
</robot>
